<sdf version='1.7'>
  <world name='default'>
    <scene>
      <ambient>0.68 0.68 0.68 1</ambient>
      <sky>
        <sunrise>6</sunrise>
        <clouds>
          <speed>12</speed>
        </clouds>
      </sky>
      <background>0.7 0.7 0.7 1</background>
      <shadows>1</shadows>
    </scene>
    <physics name='default_physics' default='0' type='ode'>
      <max_step_size>0.001</max_step_size>
      <real_time_factor>1</real_time_factor>
      <real_time_update_rate>1000</real_time_update_rate>
    </physics>
    <model name='ISCAS_groundplane'>
      <static>1</static>
      <link name='link'>
        <collision name='collision'>
          <geometry>
            <plane>
              <normal>0 0 1</normal>
              <size>12 13</size>
            </plane>
          </geometry>
          <surface>
            <friction>
              <ode>
                <mu>100</mu>
                <mu2>50</mu2>
              </ode>
              <torsional>
                <ode/>
              </torsional>
            </friction>
            <contact>
              <ode/>
            </contact>
            <bounce/>
          </surface>
          <max_contacts>10</max_contacts>
        </collision>
        <visual name='visual'>
          <cast_shadows>0</cast_shadows>
          <geometry>
            <plane>
              <normal>0 0 1</normal>
              <size>12 13</size>
            </plane>
          </geometry>
          <material>
            <script>
              <uri>model://ISCAS_groundplane/materials/scripts</uri>
              <uri>model://ISCAS_groundplane/materials/textures</uri>
              <name>ISCAS_groundplane/Image</name>
            </script>
          </material>
        </visual>
        <self_collide>0</self_collide>
        <enable_wind>0</enable_wind>
        <kinematic>0</kinematic>
      </link>
    </model>
    <light name='sun' type='directional'>
      <cast_shadows>1</cast_shadows>
      <pose>0 0 10 0 -0 0</pose>
      <diffuse>0.8 0.8 0.8 1</diffuse>
      <specular>0.2 0.2 0.2 1</specular>
      <attenuation>
        <range>1000</range>
        <constant>0.9</constant>
        <linear>0.01</linear>
        <quadratic>0.001</quadratic>
      </attenuation>
      <direction>-0.5 0.1 -0.9</direction>
      <spot>
        <inner_angle>0</inner_angle>
        <outer_angle>0</outer_angle>
        <falloff>0</falloff>
      </spot>
    </light>
    <model name='ISCAS_Museum'>
      <link name='link'>
        <inertial>
          <mass>15</mass>
          <inertia>
            <ixx>0</ixx>
            <ixy>0</ixy>
            <ixz>0</ixz>
            <iyy>0</iyy>
            <iyz>0</iyz>
            <izz>0</izz>
          </inertia>
        </inertial>
        <collision name='collision'>
          <pose>0 0 0 0 -0 0</pose>
          <geometry>
            <mesh>
              <uri>model://ISCAS_Museum/meshes/ISCASmuseum.obj</uri>
            </mesh>
          </geometry>
          <max_contacts>10</max_contacts>
          <surface>
            <contact>
              <ode/>
            </contact>
            <bounce/>
            <friction>
              <torsional>
                <ode/>
              </torsional>
              <ode/>
            </friction>
          </surface>
        </collision>
        <visual name='visual'>
          <pose>0 0 0 0 -0 0</pose>
          <geometry>
            <mesh>
              <uri>model://ISCAS_Museum/meshes/ISCASmuseum.obj</uri>
            </mesh>
          </geometry>
        </visual>
        <self_collide>0</self_collide>
        <enable_wind>0</enable_wind>
        <kinematic>0</kinematic>
      </link>
      <static>1</static>
      <pose>0 0 0 0 0 -1.57</pose>
    </model>
    <gravity>0 0 -9.8</gravity>
    <magnetic_field>6e-06 2.3e-05 -4.2e-05</magnetic_field>
    <atmosphere type='adiabatic'/>
    <wind/>
    <spherical_coordinates>
      <surface_model>EARTH_WGS84</surface_model>
      <latitude_deg>0</latitude_deg>
      <longitude_deg>0</longitude_deg>
      <elevation>0</elevation>
      <heading_deg>0</heading_deg>
    </spherical_coordinates>
    <model name='unit_box'>
      <pose>3.61772 5.71173 0.5 0 -0 0</pose>
      <link name='link'>
        <inertial>
          <mass>1</mass>
          <inertia>
            <ixx>0.166667</ixx>
            <ixy>0</ixy>
            <ixz>0</ixz>
            <iyy>0.166667</iyy>
            <iyz>0</iyz>
            <izz>0.166667</izz>
          </inertia>
          <pose>0 0 0 0 -0 0</pose>
        </inertial>
        <collision name='collision'>
          <geometry>
            <box>
              <size>1 1 0.999999</size>
            </box>
          </geometry>
          <max_contacts>10</max_contacts>
          <surface>
            <contact>
              <ode/>
            </contact>
            <bounce/>
            <friction>
              <torsional>
                <ode/>
              </torsional>
              <ode/>
            </friction>
          </surface>
        </collision>
        <visual name='visual'>
          <geometry>
            <box>
              <size>1 1 0.999999</size>
            </box>
          </geometry>
          <material>
            <script>
              <name>Gazebo/Grey</name>
              <uri>file://media/materials/scripts/gazebo.material</uri>
            </script>
          </material>
        </visual>
        <self_collide>0</self_collide>
        <enable_wind>0</enable_wind>
        <kinematic>0</kinematic>
      </link>
    </model>
    <model name='unit_box_clone'>
      <pose>2.73198 5.83518 0.433022 -0 -0 -0.002023</pose>
      <link name='link'>
        <inertial>
          <mass>1</mass>
          <inertia>
            <ixx>0.166667</ixx>
            <ixy>0</ixy>
            <ixz>0</ixz>
            <iyy>0.166667</iyy>
            <iyz>0</iyz>
            <izz>0.166667</izz>
          </inertia>
          <pose>0 0 0 0 -0 0</pose>
        </inertial>
        <collision name='collision'>
          <geometry>
            <box>
              <size>1 0.185442 0.866044</size>
            </box>
          </geometry>
          <max_contacts>10</max_contacts>
          <surface>
            <contact>
              <ode/>
            </contact>
            <bounce/>
            <friction>
              <torsional>
                <ode/>
              </torsional>
              <ode/>
            </friction>
          </surface>
        </collision>
        <visual name='visual'>
          <geometry>
            <box>
              <size>1 0.185442 0.866044</size>
            </box>
          </geometry>
          <material>
            <script>
              <name>Gazebo/Grey</name>
              <uri>file://media/materials/scripts/gazebo.material</uri>
            </script>
          </material>
        </visual>
        <self_collide>0</self_collide>
        <enable_wind>0</enable_wind>
        <kinematic>0</kinematic>
      </link>
    </model>
    <state world_name='default'>
      <sim_time>158 537000000</sim_time>
      <real_time>79 995014433</real_time>
      <wall_time>1719541002 902775010</wall_time>
      <iterations>78889</iterations>
      <model name='ISCAS_Museum'>
        <pose>0 0 0 0 -0 3.12642</pose>
        <scale>1 1 1</scale>
        <link name='link'>
          <pose>0 0 0 0 -0 3.12642</pose>
          <velocity>0 0 0 0 -0 0</velocity>
          <acceleration>0 0 0 0 -0 0</acceleration>
          <wrench>0 0 0 0 -0 0</wrench>
        </link>
      </model>
      <model name='ISCAS_groundplane'>
        <pose>0 0 0 0 -0 0</pose>
        <scale>1 1 1</scale>
        <link name='link'>
          <pose>0 0 0 0 -0 0</pose>
          <velocity>0 0 0 0 -0 0</velocity>
          <acceleration>0 0 0 0 -0 0</acceleration>
          <wrench>0 0 0 0 -0 0</wrench>
        </link>
      </model>
      <model name='my_robot'>
        <pose>0.000517 0.000488 0 -1e-06 -0 -0.000334</pose>
        <scale>1 1 1</scale>
        <link name='base_footprint'>
          <pose>0.000517 0.000488 0 -1e-06 -0 -0.000334</pose>
          <velocity>9e-06 5e-06 0.001939 -0.000126 -0.000268 -4e-06</velocity>
          <acceleration>-0.192581 0.089856 3.88063 -0.251768 -0.536039 -0.000176</acceleration>
          <wrench>-7.89583 3.68411 159.106 0 -0 0</wrench>
        </link>
        <link name='fl_wheel_link'>
          <pose>0.205579 0.185419 0.075 -1e-06 0.000489 -0.000334</pose>
          <velocity>-1.9e-05 1.6e-05 0.002003 -0.000217 -0.000256 -5e-06</velocity>
          <acceleration>-0.053064 0.021941 4.00602 -0.433902 -0.523587 -0.001155</acceleration>
          <wrench>-0.265321 0.109704 20.0301 0 -0 0</wrench>
        </link>
        <link name='fr_wheel_link'>
          <pose>0.205455 -0.184581 0.075 -1e-06 0.000615 -0.000334</pose>
          <velocity>-1.9e-05 1.9e-05 0.002008 -0.000249 -0.000252 -5e-06</velocity>
          <acceleration>-0.049466 0.026756 4.01693 -0.498145 -0.520334 -0.002395</acceleration>
          <wrench>-0.247328 0.133781 20.0846 0 -0 0</wrench>
        </link>
        <link name='rl_wheel_link'>
          <pose>-0.204421 0.185556 0.075 -1e-06 0.000714 -0.000334</pose>
          <velocity>-1.9e-05 1.8e-05 0.001861 -0.000244 -0.00025 -6e-06</velocity>
          <acceleration>-0.052159 0.022555 3.72287 -0.488219 -0.51748 -0.002915</acceleration>
          <wrench>-0.260797 0.112774 18.6144 0 -0 0</wrench>
        </link>
        <link name='rr_wheel_link'>
          <pose>-0.204545 -0.184444 0.075 -1e-06 0.000471 -0.000334</pose>
          <velocity>-1.9e-05 2.1e-05 0.001867 -0.000275 -0.000256 -6e-06</velocity>
          <acceleration>-0.049981 0.02727 3.73416 -0.55113 -0.523719 -0.00337</acceleration>
          <wrench>-0.249905 0.136352 18.6708 0 -0 0</wrench>
        </link>
      </model>
      <model name='unit_box'>
        <pose>3.73807 5.80746 0.433018 -1e-06 -1e-06 -0.002007</pose>
        <scale>1 0.185442 0.866045</scale>
        <link name='link'>
          <pose>3.73807 5.80746 0.433018 -1e-06 -1e-06 -0.002007</pose>
          <velocity>0 0 0 0 -0 0</velocity>
          <acceleration>0 0 -9.8 0 -0 0</acceleration>
          <wrench>0 0 -9.8 0 -0 0</wrench>
        </link>
      </model>
      <model name='unit_box_clone'>
        <pose>2.73193 5.81227 0.433017 -1e-06 -1e-06 -0.002007</pose>
        <scale>1 1 1</scale>
        <link name='link'>
          <pose>2.73193 5.81227 0.433017 -1e-06 -1e-06 -0.002007</pose>
          <velocity>0 0 0 0 -0 0</velocity>
          <acceleration>0 0 -9.8 0 -0 0</acceleration>
          <wrench>0 0 -9.8 0 -0 0</wrench>
        </link>
      </model>
      <light name='sun'>
        <pose>0 0 10 0 -0 0</pose>
      </light>
    </state>
    <gui fullscreen='0'>
      <camera name='user_camera'>
        <pose>11.3186 15.061 24.7385 0 0.965797 -2.05898</pose>
        <view_controller>orbit</view_controller>
        <projection_type>perspective</projection_type>
      </camera>
    </gui>
    <audio>
      <device>default</device>
    </audio>
    <model name='my_robot'>
      <link name='base_footprint'>
        <inertial>
          <pose>0.003537 -0 0.366585 0 -0 0</pose>
          <mass>41</mass>
          <inertia>
            <ixx>10.4535</ixx>
            <ixy>-3.9264e-19</ixy>
            <ixz>0.0234299</ixz>
            <iyy>10.8757</iyy>
            <iyz>-3.73685e-17</iyz>
            <izz>6.28239</izz>
          </inertia>
        </inertial>
        <collision name='base_footprint_fixed_joint_lump__base_link_collision'>
          <pose>0 0 0.105 0 -0 0</pose>
          <geometry>
            <box>
              <size>0.41 0.32 0.15</size>
            </box>
          </geometry>
          <surface>
            <contact>
              <ode/>
            </contact>
            <friction>
              <ode/>
              <torsional>
                <ode/>
              </torsional>
            </friction>
            <bounce/>
          </surface>
          <max_contacts>10</max_contacts>
        </collision>
        <collision name='base_footprint_fixed_joint_lump__left_front_pillar_link_collision_1'>
          <pose>0.05 -0.07 0.46 0 -0 0</pose>
          <geometry>
            <box>
              <size>0.05 0.02 0.56</size>
            </box>
          </geometry>
          <max_contacts>10</max_contacts>
          <surface>
            <contact>
              <ode/>
            </contact>
            <bounce/>
            <friction>
              <torsional>
                <ode/>
              </torsional>
              <ode/>
            </friction>
          </surface>
        </collision>
        <collision name='base_footprint_fixed_joint_lump__left_rear_pillar_link_collision_2'>
          <pose>-0.05 -0.07 0.46 0 -0 0</pose>
          <geometry>
            <box>
              <size>0.05 0.02 0.56</size>
            </box>
          </geometry>
          <max_contacts>10</max_contacts>
          <surface>
            <contact>
              <ode/>
            </contact>
            <bounce/>
            <friction>
              <torsional>
                <ode/>
              </torsional>
              <ode/>
            </friction>
          </surface>
        </collision>
        <collision name='base_footprint_fixed_joint_lump__lidar_link_collision_3'>
          <pose>0.145 0 0.205 0 -0 0</pose>
          <geometry>
            <cylinder>
              <length>0.1</length>
              <radius>0.075</radius>
            </cylinder>
          </geometry>
          <surface>
            <contact>
              <ode/>
            </contact>
            <friction>
              <ode/>
              <torsional>
                <ode/>
              </torsional>
            </friction>
            <bounce/>
          </surface>
          <max_contacts>10</max_contacts>
        </collision>
        <collision name='base_footprint_fixed_joint_lump__right_front_pillar_link_collision_4'>
          <pose>0.05 0.07 0.46 0 -0 0</pose>
          <geometry>
            <box>
              <size>0.05 0.02 0.56</size>
            </box>
          </geometry>
          <max_contacts>10</max_contacts>
          <surface>
            <contact>
              <ode/>
            </contact>
            <bounce/>
            <friction>
              <torsional>
                <ode/>
              </torsional>
              <ode/>
            </friction>
          </surface>
        </collision>
        <collision name='base_footprint_fixed_joint_lump__right_rear_pillar_link_collision_5'>
          <pose>-0.05 0.07 0.46 0 -0 0</pose>
          <geometry>
            <box>
              <size>0.05 0.02 0.56</size>
            </box>
          </geometry>
          <max_contacts>10</max_contacts>
          <surface>
            <contact>
              <ode/>
            </contact>
            <bounce/>
            <friction>
              <torsional>
                <ode/>
              </torsional>
              <ode/>
            </friction>
          </surface>
        </collision>
        <collision name='base_footprint_fixed_joint_lump__upper_platform_link_collision_6'>
          <pose>0 0 0.81 0 -0 0</pose>
          <geometry>
            <box>
              <size>0.16 0.21 0.14</size>
            </box>
          </geometry>
          <surface>
            <contact>
              <ode/>
            </contact>
            <friction>
              <ode/>
              <torsional>
                <ode/>
              </torsional>
            </friction>
            <bounce/>
          </surface>
          <max_contacts>10</max_contacts>
        </collision>
        <visual name='base_footprint_fixed_joint_lump__base_link_visual'>
          <pose>0 0 0.105 0 -0 0</pose>
          <geometry>
            <box>
              <size>0.41 0.32 0.15</size>
            </box>
          </geometry>
          <material>
            <script>
              <name>Gazebo/Blue</name>
              <uri>file://media/materials/scripts/gazebo.material</uri>
            </script>
          </material>
        </visual>
        <visual name='base_footprint_fixed_joint_lump__imu_link_visual_1'>
          <pose>0 0 0.03 0 -0 0</pose>
          <geometry>
            <box>
              <size>0.1 0.1 0.01</size>
            </box>
          </geometry>
          <material>
            <script>
              <name>Gazebo/Grey</name>
              <uri>file://media/materials/scripts/gazebo.material</uri>
            </script>
          </material>
        </visual>
        <visual name='base_footprint_fixed_joint_lump__left_front_pillar_link_visual_2'>
          <pose>0.05 -0.07 0.46 0 -0 0</pose>
          <geometry>
            <box>
              <size>0.05 0.02 0.56</size>
            </box>
          </geometry>
        </visual>
        <visual name='base_footprint_fixed_joint_lump__left_rear_pillar_link_visual_3'>
          <pose>-0.05 -0.07 0.46 0 -0 0</pose>
          <geometry>
            <box>
              <size>0.05 0.02 0.56</size>
            </box>
          </geometry>
        </visual>
        <visual name='base_footprint_fixed_joint_lump__lidar_link_visual_4'>
          <pose>0.145 0 0.205 0 -0 0</pose>
          <geometry>
            <cylinder>
              <length>0.05</length>
              <radius>0.03</radius>
            </cylinder>
          </geometry>
          <material>
            <script>
              <name>Gazebo/Black</name>
              <uri>file://media/materials/scripts/gazebo.material</uri>
            </script>
          </material>
        </visual>
        <visual name='base_footprint_fixed_joint_lump__right_front_pillar_link_visual_5'>
          <pose>0.05 0.07 0.46 0 -0 0</pose>
          <geometry>
            <box>
              <size>0.05 0.02 0.56</size>
            </box>
          </geometry>
        </visual>
        <visual name='base_footprint_fixed_joint_lump__right_rear_pillar_link_visual_6'>
          <pose>-0.05 0.07 0.46 0 -0 0</pose>
          <geometry>
            <box>
              <size>0.05 0.02 0.56</size>
            </box>
          </geometry>
        </visual>
        <visual name='base_footprint_fixed_joint_lump__upper_platform_link_visual_7'>
          <pose>0 0 0.81 0 -0 0</pose>
          <geometry>
            <box>
              <size>0.16 0.21 0.14</size>
            </box>
          </geometry>
          <material>
            <script>
              <name>Gazebo/Blue</name>
              <uri>file://media/materials/scripts/gazebo.material</uri>
            </script>
          </material>
        </visual>
        <visual name='base_footprint_fixed_joint_lump__camera_link_visual_8'>
          <pose>0.085 0 0.81 0 -0 0</pose>
          <geometry>
            <box>
              <size>0.01 0.1 0.05</size>
            </box>
          </geometry>
          <material>
            <script>
              <name>Gazebo/Red</name>
              <uri>file://media/materials/scripts/gazebo.material</uri>
            </script>
          </material>
        </visual>
        <gravity>1</gravity>
        <sensor name='imu_sensor' type='imu'>
          <always_on>1</always_on>
          <update_rate>10</update_rate>
          <visualize>1</visualize>
          <plugin name='imu' filename='libgazebo_ros_imu_sensor.so'>
            <ros>
              <argument>~/out:=imu</argument>
            </ros>
            <bodyName>imu_link</bodyName>
            <updateRateHZ>10.0</updateRateHZ>
            <gaussianNoise>0.0</gaussianNoise>
            <xyzOffset>0 0 0</xyzOffset>
            <rpyOffset>0 0 0</rpyOffset>
            <frameName>imu_link</frameName>
            <initialOrientationAsReference>0</initialOrientationAsReference>
          </plugin>
          <pose>0 0 0.03 0 -0 0</pose>
          <imu/>
        </sensor>
        <sensor name='lidar' type='ray'>
          <visualize>1</visualize>
          <update_rate>10</update_rate>
          <ray>
            <scan>
              <horizontal>
                <samples>360</samples>
                <resolution>1</resolution>
                <min_angle>-1.57</min_angle>
                <max_angle>1.57</max_angle>
              </horizontal>
              <vertical>
                <samples>1</samples>
                <min_angle>0</min_angle>
                <max_angle>0</max_angle>
              </vertical>
            </scan>
            <range>
              <min>0.15</min>
              <max>7</max>
              <resolution>0.01</resolution>
            </range>
            <noise>
              <type>gaussian</type>
              <mean>0</mean>
              <stddev>0.01</stddev>
            </noise>
          </ray>
          <plugin name='scan' filename='libgazebo_ros_ray_sensor.so'>
            <ros>
              <argument>~/out:=/scan</argument>
            </ros>
            <output_type>sensor_msgs/LaserScan</output_type>
            <frame_name>lidar_link</frame_name>
          </plugin>
          <pose>0.145 0 0.205 0 -0 0</pose>
        </sensor>
        <sensor name='camera_sensor' type='camera'>
          <visualize>1</visualize>
          <update_rate>30</update_rate>
          <plugin name='camera_controller' filename='libgazebo_ros_camera.so'>
            <frame_name>camera_link</frame_name>
          </plugin>
          <pose>0.085 0 0.81 0 -0 0</pose>
          <camera>
            <horizontal_fov>1.047</horizontal_fov>
            <image>
              <width>320</width>
              <height>240</height>
            </image>
            <clip>
              <near>0.1</near>
              <far>100</far>
            </clip>
          </camera>
        </sensor>
        <self_collide>0</self_collide>
        <enable_wind>0</enable_wind>
        <kinematic>0</kinematic>
      </link>
      <joint name='fl_wheel_joint' type='revolute'>
        <pose relative_to='base_footprint'>0.205 0.185 0.075 0 -0 0</pose>
        <parent>base_footprint</parent>
        <child>fl_wheel_link</child>
        <axis>
          <xyz>0 1 0</xyz>
          <limit>
            <lower>-1e+16</lower>
            <upper>1e+16</upper>
          </limit>
          <dynamics>
            <spring_reference>0</spring_reference>
            <spring_stiffness>0</spring_stiffness>
          </dynamics>
        </axis>
      </joint>
      <link name='fl_wheel_link'>
        <pose relative_to='fl_wheel_joint'>0 0 0 0 -0 0</pose>
        <inertial>
          <pose>0 0 0 1.5708 -0 0</pose>
          <mass>5</mass>
          <inertia>
            <ixx>0.201823</ixx>
            <ixy>0</ixy>
            <ixz>0</ixz>
            <iyy>0.201823</iyy>
            <iyz>0</iyz>
            <izz>0.351562</izz>
          </inertia>
        </inertial>
        <collision name='fl_wheel_link_collision'>
          <pose>0 0 0 1.5708 -0 0</pose>
          <geometry>
            <cylinder>
              <length>0.05</length>
              <radius>0.075</radius>
            </cylinder>
          </geometry>
          <surface>
            <contact>
              <ode/>
            </contact>
            <friction>
              <ode>
                <mu>0.1</mu>
                <mu2>0.1</mu2>
              </ode>
              <torsional>
                <ode/>
              </torsional>
            </friction>
            <bounce/>
          </surface>
          <max_contacts>10</max_contacts>
        </collision>
        <visual name='fl_wheel_link_visual'>
          <pose>0 0 0 1.5708 -0 0</pose>
          <geometry>
            <cylinder>
              <length>0.05</length>
              <radius>0.075</radius>
            </cylinder>
          </geometry>
          <material>
            <script>
              <name>Gazebo/Grey</name>
              <uri>file://media/materials/scripts/gazebo.material</uri>
            </script>
          </material>
        </visual>
        <self_collide>0</self_collide>
        <enable_wind>0</enable_wind>
        <kinematic>0</kinematic>
      </link>
      <joint name='fr_wheel_joint' type='revolute'>
        <pose relative_to='base_footprint'>0.205 -0.185 0.075 0 -0 0</pose>
        <parent>base_footprint</parent>
        <child>fr_wheel_link</child>
        <axis>
          <xyz>0 1 0</xyz>
          <limit>
            <lower>-1e+16</lower>
            <upper>1e+16</upper>
          </limit>
          <dynamics>
            <spring_reference>0</spring_reference>
            <spring_stiffness>0</spring_stiffness>
          </dynamics>
        </axis>
      </joint>
      <link name='fr_wheel_link'>
        <pose relative_to='fr_wheel_joint'>0 0 0 0 -0 0</pose>
        <inertial>
          <pose>0 0 0 1.5708 -0 0</pose>
          <mass>5</mass>
          <inertia>
            <ixx>0.201823</ixx>
            <ixy>0</ixy>
            <ixz>0</ixz>
            <iyy>0.201823</iyy>
            <iyz>0</iyz>
            <izz>0.351562</izz>
          </inertia>
        </inertial>
        <collision name='fr_wheel_link_collision'>
          <pose>0 0 0 1.5708 -0 0</pose>
          <geometry>
            <cylinder>
              <length>0.05</length>
              <radius>0.075</radius>
            </cylinder>
          </geometry>
          <surface>
            <contact>
              <ode/>
            </contact>
            <friction>
              <ode>
                <mu>0.1</mu>
                <mu2>0.1</mu2>
              </ode>
              <torsional>
                <ode/>
              </torsional>
            </friction>
            <bounce/>
          </surface>
          <max_contacts>10</max_contacts>
        </collision>
        <visual name='fr_wheel_link_visual'>
          <pose>0 0 0 1.5708 -0 0</pose>
          <geometry>
            <cylinder>
              <length>0.05</length>
              <radius>0.075</radius>
            </cylinder>
          </geometry>
          <material>
            <script>
              <name>Gazebo/Grey</name>
              <uri>file://media/materials/scripts/gazebo.material</uri>
            </script>
          </material>
        </visual>
        <self_collide>0</self_collide>
        <enable_wind>0</enable_wind>
        <kinematic>0</kinematic>
      </link>
      <joint name='rl_wheel_joint' type='revolute'>
        <pose relative_to='base_footprint'>-0.205 0.185 0.075 0 -0 0</pose>
        <parent>base_footprint</parent>
        <child>rl_wheel_link</child>
        <axis>
          <xyz>0 1 0</xyz>
          <limit>
            <lower>-1e+16</lower>
            <upper>1e+16</upper>
          </limit>
          <dynamics>
            <spring_reference>0</spring_reference>
            <spring_stiffness>0</spring_stiffness>
          </dynamics>
        </axis>
      </joint>
      <link name='rl_wheel_link'>
        <pose relative_to='rl_wheel_joint'>0 0 0 0 -0 0</pose>
        <inertial>
          <pose>0 0 0 1.5708 -0 0</pose>
          <mass>5</mass>
          <inertia>
            <ixx>0.201823</ixx>
            <ixy>0</ixy>
            <ixz>0</ixz>
            <iyy>0.201823</iyy>
            <iyz>0</iyz>
            <izz>0.351562</izz>
          </inertia>
        </inertial>
        <collision name='rl_wheel_link_collision'>
          <pose>0 0 0 1.5708 -0 0</pose>
          <geometry>
            <cylinder>
              <length>0.05</length>
              <radius>0.075</radius>
            </cylinder>
          </geometry>
          <surface>
            <contact>
              <ode/>
            </contact>
            <friction>
              <ode/>
              <torsional>
                <ode/>
              </torsional>
            </friction>
            <bounce/>
          </surface>
          <max_contacts>10</max_contacts>
        </collision>
        <visual name='rl_wheel_link_visual'>
          <pose>0 0 0 1.5708 -0 0</pose>
          <geometry>
            <cylinder>
              <length>0.05</length>
              <radius>0.075</radius>
            </cylinder>
          </geometry>
          <material>
            <script>
              <name>Gazebo/Grey</name>
              <uri>file://media/materials/scripts/gazebo.material</uri>
            </script>
          </material>
        </visual>
        <self_collide>0</self_collide>
        <enable_wind>0</enable_wind>
        <kinematic>0</kinematic>
      </link>
      <joint name='rr_wheel_joint' type='revolute'>
        <pose relative_to='base_footprint'>-0.205 -0.185 0.075 0 -0 0</pose>
        <parent>base_footprint</parent>
        <child>rr_wheel_link</child>
        <axis>
          <xyz>0 1 0</xyz>
          <limit>
            <lower>-1e+16</lower>
            <upper>1e+16</upper>
          </limit>
          <dynamics>
            <spring_reference>0</spring_reference>
            <spring_stiffness>0</spring_stiffness>
          </dynamics>
        </axis>
      </joint>
      <link name='rr_wheel_link'>
        <pose relative_to='rr_wheel_joint'>0 0 0 0 -0 0</pose>
        <inertial>
          <pose>0 0 0 1.5708 -0 0</pose>
          <mass>5</mass>
          <inertia>
            <ixx>0.201823</ixx>
            <ixy>0</ixy>
            <ixz>0</ixz>
            <iyy>0.201823</iyy>
            <iyz>0</iyz>
            <izz>0.351562</izz>
          </inertia>
        </inertial>
        <collision name='rr_wheel_link_collision'>
          <pose>0 0 0 1.5708 -0 0</pose>
          <geometry>
            <cylinder>
              <length>0.05</length>
              <radius>0.075</radius>
            </cylinder>
          </geometry>
          <surface>
            <contact>
              <ode/>
            </contact>
            <friction>
              <ode/>
              <torsional>
                <ode/>
              </torsional>
            </friction>
            <bounce/>
          </surface>
          <max_contacts>10</max_contacts>
        </collision>
        <visual name='rr_wheel_link_visual'>
          <pose>0 0 0 1.5708 -0 0</pose>
          <geometry>
            <cylinder>
              <length>0.05</length>
              <radius>0.075</radius>
            </cylinder>
          </geometry>
          <material>
            <script>
              <name>Gazebo/Grey</name>
              <uri>file://media/materials/scripts/gazebo.material</uri>
            </script>
          </material>
        </visual>
        <self_collide>0</self_collide>
        <enable_wind>0</enable_wind>
        <kinematic>0</kinematic>
      </link>
      <plugin name='diff_drive_control' filename='libgazebo_ros_diff_drive.so'>
        <update_rate>50</update_rate>
        <left_joint>rl_wheel_joint</left_joint>
        <right_joint>rr_wheel_joint</right_joint>
        <wheel_separation>0.45</wheel_separation>
        <wheel_diameter>0.2</wheel_diameter>
        <publish_odom>1</publish_odom>
        <publish_odom_tf>1</publish_odom_tf>
        <publish_wheel_tf>1</publish_wheel_tf>
        <odometry_topic>odom</odometry_topic>
        <odometry_frame>odom</odometry_frame>
        <robot_base_frame>base_footprint</robot_base_frame>
      </plugin>
      <static>0</static>
      <plugin name='driven_wheel' filename='libgazebo_ros_diff_drive.so'>
        <update_rate>50</update_rate>
        <left_joint>fl_wheel_joint</left_joint>
        <right_joint>fr_wheel_joint</right_joint>
        <wheel_separation>0.45</wheel_separation>
        <wheel_diameter>0.2</wheel_diameter>
        <publish_odom>0</publish_odom>
        <publish_odom_tf>0</publish_odom_tf>
        <publish_wheel_tf>1</publish_wheel_tf>
        <robot_base_frame>base_footprint</robot_base_frame>
      </plugin>
      <pose>0 0 0 0 -0 0</pose>
    </model>
  </world>
</sdf>
